Workbook

Sheet Stående
A1: Varighed for 10-årig stående obligation – eksemplet i kapitel 4
A2: Gule felter med blå tekst er input og kan ændres; alt andet er formler. Prøv fx at ændre den effektive rente.
A4: Nøgledata (tabel 4.2)
A5: Handelsdag | B5: 45678 | C5: Handelsdagen bruges ikke i beregningen – valørdagen gør.
A6: Valørdag | B6: 45680 | C6: Dagen hvor betaling og levering sker; tider måles herfra.
A7: Sidste kuponbetaling | B7: 45611 | C7: Start på den løbende kuponperiode.
A8: Næste kupondato (første termin) | B8: 45976 | C8: Slut på den løbende kuponperiode.
A9: Kupon (p.a.) | B9: 0.0225
A10: Effektiv rente | B10: 0.0245 | C10: Diskonteringsrenten for alle betalinger.
A11: Terminer pr. år, n | B11: 1 | C11: Årlige terminer i eksemplet.
A12: Hovedstol | B12: 100
A13: Antal resterende betalinger | B13: 10 | C13: 2025, 2026, …, 2034.
A15: Afledte størrelser
A16: Antal vedh. rentedage | B16: =B6-B7 -> 69 | C16: Faktiske dage fra sidste kupon til valør (tabel 4.2: 69).
A17: Dage i kuponperioden | B17: =B8-B7 -> 365 | C17: 15-11-2024 → 15-11-2025 = 365 faktiske dage.
A18: Dage fra valør til første termin | B18: =B8-B6 -> 296 | C18: 23-01-2025 → 15-11-2025 = 296 faktiske dage.
A19: t1 (ACT/ACT) | B19: =B18/B17 -> 0.8109589 | C19: t1 = 296/365 = 0,811. Svarer til bogens =(B3-B1)/(B3-B2).
A20: Vedhængende rente | B20: =B9*B12/B11*B16/B17 -> 0.42534247 | C20: Kupon × 69/365 (tabel 4.2: 0,425).
A22: Trin 1: Den første betaling
A23: Kuponbetaling | B23: =B9*B12/B11 -> 2.25
A24: Diskonteringsfaktor 1/(1+r)^t1 | B24: =1/(1+B10)^B19 -> 0.98056239
A25: Nutidsværdi | B25: =B23*B24 -> 2.2062654 | C25: 2,25 / 1,0245^0,811 = 2,206. Samme beregning gentages for hver betaling nedenfor.
A27: Trin 2: Alle betalinger (tabel 4.3)
A28: Nr. | B28: Termin | C28: Tid i år t_i | D28: CF | E28: Disk.faktor | F28: PV(CF) | G28: Vægt | H28: Vægt·tid | I28: t_i(t_i+1)·PV(CF)
A29: 1 | B29: =$B$8 -> 45976 | C29: =$B$19 -> 0.8109589 | D29: =$B$9*$B$12/$B$11+IF(A29=$B$13,$B$12,0) -> 2.25 | E29: =1/(1+$B$10)^C29 -> 0.98056239 | F29: =D29*E29 -> 2.2062654 | G29: =F29/$F$39 -> 0.022354237 | H29: =G29*C29 -> 0.018128368 | I29: =C29*(C29+1)*F29 -> 3.2401506
A30: 2 | B30: =EDATE(B29,12/$B$11) -> 46341 | C30: =C29+1/$B$11 -> 1.8109589 | D30: =$B$9*$B$12/$B$11+IF(A30=$B$13,$B$12,0) -> 2.25 | E30: =1/(1+$B$10)^C30 -> 0.95711312 | F30: =D30*E30 -> 2.1535045 | G30: =F30/$F$39 -> 0.021819655 | H30: =G30*C30 -> 0.039514499 | I30: =C30*(C30+1)*F30 -> 10.962482
A31: 3 | B31: =EDATE(B30,12/$B$11) -> 46706 | C31: =C30+1/$B$11 -> 2.8109589 | D31: =$B$9*$B$12/$B$11+IF(A31=$B$13,$B$12,0) -> 2.25 | E31: =1/(1+$B$10)^C31 -> 0.93422461 | F31: =D31*E31 -> 2.1020054 | G31: =F31/$F$39 -> 0.021297858 | H31: =G31*C31 -> 0.059867403 | I31: =C31*(C31+1)*F31 -> 22.517625
A32: 4 | B32: =EDATE(B31,12/$B$11) -> 47072 | C32: =C31+1/$B$11 -> 3.8109589 | D32: =$B$9*$B$12/$B$11+IF(A32=$B$13,$B$12,0) -> 2.25 | E32: =1/(1+$B$10)^C32 -> 0.91188347 | F32: =D32*E32 -> 2.0517378 | G32: =F32/$F$39 -> 0.020788539 | H32: =G32*C32 -> 0.079224267 | I32: =C32*(C32+1)*F32 -> 37.617313
A33: 5 | B33: =EDATE(B32,12/$B$11) -> 47437 | C33: =C32+1/$B$11 -> 4.8109589 | D33: =$B$9*$B$12/$B$11+IF(A33=$B$13,$B$12,0) -> 2.25 | E33: =1/(1+$B$10)^C33 -> 0.89007659 | F33: =D33*E33 -> 2.0026723 | G33: =F33/$F$39 -> 0.020291399 | H33: =G33*C33 -> 0.097621089 | I33: =C33*(C33+1)*F33 -> 55.987277
A34: 6 | B34: =EDATE(B33,12/$B$11) -> 47802 | C34: =C33+1/$B$11 -> 5.8109589 | D34: =$B$9*$B$12/$B$11+IF(A34=$B$13,$B$12,0) -> 2.25 | E34: =1/(1+$B$10)^C34 -> 0.86879121 | F34: =D34*E34 -> 1.9547802 | G34: =F34/$F$39 -> 0.019806149 | H34: =G34*C34 -> 0.11509272 | I34: =C34*(C34+1)*F34 -> 77.366687
A35: 7 | B35: =EDATE(B34,12/$B$11) -> 48167 | C35: =C34+1/$B$11 -> 6.8109589 | D35: =$B$9*$B$12/$B$11+IF(A35=$B$13,$B$12,0) -> 2.25 | E35: =1/(1+$B$10)^C35 -> 0.84801484 | F35: =D35*E35 -> 1.9080334 | G35: =F35/$F$39 -> 0.019332502 | H35: =G35*C35 -> 0.13167288 | I35: =C35*(C35+1)*F35 -> 101.50761
A36: 8 | B36: =EDATE(B35,12/$B$11) -> 48533 | C36: =C35+1/$B$11 -> 7.8109589 | D36: =$B$9*$B$12/$B$11+IF(A36=$B$13,$B$12,0) -> 2.25 | E36: =1/(1+$B$10)^C36 -> 0.82773533 | F36: =D36*E36 -> 1.8624045 | G36: =F36/$F$39 -> 0.018870183 | H36: =G36*C36 -> 0.14739422 | I36: =C36*(C36+1)*F36 -> 128.17447
A37: 9 | B37: =EDATE(B36,12/$B$11) -> 48898 | C37: =C36+1/$B$11 -> 8.8109589 | D37: =$B$9*$B$12/$B$11+IF(A37=$B$13,$B$12,0) -> 2.25 | E37: =1/(1+$B$10)^C37 -> 0.80794078 | F37: =D37*E37 -> 1.8178668 | G37: =F37/$F$39 -> 0.018418919 | H37: =G37*C37 -> 0.16228834 | I37: =C37*(C37+1)*F37 -> 157.14359
A38: 10 | B38: =EDATE(B37,12/$B$11) -> 49263 | C38: =C37+1/$B$11 -> 9.8109589 | D38: =$B$9*$B$12/$B$11+IF(A38=$B$13,$B$12,0) -> 102.25 | E38: =1/(1+$B$10)^C38 -> 0.7886196 | F38: =D38*E38 -> 80.636354 | G38: =F38/$F$39 -> 0.81702056 | H38: =G38*C38 -> 8.0157551 | I38: =C38*(C38+1)*F38 -> 8552.7653
A39: Sum | F39: =SUM(F29:F38) -> 98.695624 | G39: =SUM(G29:G38) -> 1 | H39: =SUM(H29:H38) -> 8.8665589 | I39: =SUM(I29:I38) -> 9147.2825
A40: Tid: t1 + (i−1)/n, jf. (4.2). CF: kupon hvert år + hovedstol ved sidste termin. Vægt = PV(CF)/kurs. Sidste kolonne bruges i konveksitetsafsnittet.
A42: Trin 3: Resultater
A43: Kurs inkl. vedh. rente (sum af PV) | B43: =F39 -> 98.695624 | C43: Bogen: 98,696
A44: Vedhængende rente | B44: =B20 -> 0.42534247 | C44: Jf. kapitel 2
A45: Kurs ekskl. vedh. rente (notering) | B45: =B43-B44 -> 98.270282 | C45: Kurs inkl. − vedh. rente
...

Sheet Serieobligation
A1: Varighed for tilsvarende serieobligation – 10 lige store afdrag
A2: Input hentes fra arket 'Stående' (grøn tekst), så begge obligationer følger med, når du ændrer der.
A4: Input
A5: Første termin | B5: =Stående!B8 -> 45976
A6: Kupon (p.a.) | B6: =Stående!B9 -> 0.0225
A7: Effektiv rente | B7: =Stående!B10 -> 0.0245
A8: Terminer pr. år, n | B8: =Stående!B11 -> 1
A9: Hovedstol | B9: =Stående!B12 -> 100
A10: Antal afdrag | B10: =Stående!B13 -> 10
A11: t1 | B11: =Stående!B19 -> 0.8109589
A12: Afdrag pr. termin | B12: =B9/B10 -> 10
A14: Betalinger (samme tider som den stående obligation)
A15: Nr. | B15: Termin | C15: Tid i år t_i | D15: Restgæld primo | E15: Rente | F15: Afdrag | G15: CF | H15: Disk.faktor | I15: PV(CF) | J15: Vægt | K15: Vægt·tid | L15: t_i(t_i+1)·PV(CF)
A16: 1 | B16: =$B$5 -> 45976 | C16: =$B$11 -> 0.8109589 | D16: =$B$9 -> 100 | E16: =$B$6/$B$8*D16 -> 2.25 | F16: =$B$12 -> 10 | G16: =E16+F16 -> 12.25 | H16: =1/(1+$B$7)^C16 -> 0.98056239 | I16: =G16*H16 -> 12.011889 | J16: =I16/$I$26 -> 0.12077858 | K16: =J16*C16 -> 0.097946469 | L16: =C16*(C16+1)*I16 -> 17.64082
A17: 2 | B17: =EDATE(B16,12/$B$8) -> 46341 | C17: =C16+1/$B$8 -> 1.8109589 | D17: =D16-F16 -> 90 | E17: =$B$6/$B$8*D17 -> 2.025 | F17: =$B$12 -> 10 | G17: =E17+F17 -> 12.025 | H17: =1/(1+$B$7)^C17 -> 0.95711312 | I17: =G17*H17 -> 11.509285 | J17: =I17/$I$26 -> 0.11572494 | K17: =J17*C17 -> 0.20957311 | L17: =C17*(C17+1)*I17 -> 58.588374
A18: 3 | B18: =EDATE(B17,12/$B$8) -> 46706 | C18: =C17+1/$B$8 -> 2.8109589 | D18: =D17-F17 -> 80 | E18: =$B$6/$B$8*D18 -> 1.8 | F18: =$B$12 -> 10 | G18: =E18+F18 -> 11.8 | H18: =1/(1+$B$7)^C18 -> 0.93422461 | I18: =G18*H18 -> 11.02385 | J18: =I18/$I$26 -> 0.11084393 | K18: =J18*C18 -> 0.31157774 | L18: =C18*(C18+1)*I18 -> 118.09243
A19: 4 | B19: =EDATE(B18,12/$B$8) -> 47072 | C19: =C18+1/$B$8 -> 3.8109589 | D19: =D18-F18 -> 70 | E19: =$B$6/$B$8*D19 -> 1.575 | F19: =$B$12 -> 10 | G19: =E19+F19 -> 11.575 | H19: =1/(1+$B$7)^C19 -> 0.91188347 | I19: =G19*H19 -> 10.555051 | J19: =I19/$I$26 -> 0.10613019 | K19: =J19*C19 -> 0.40445781 | L19: =C19*(C19+1)*I19 -> 193.52018
A20: 5 | B20: =EDATE(B19,12/$B$8) -> 47437 | C20: =C19+1/$B$8 -> 4.8109589 | D20: =D19-F19 -> 60 | E20: =$B$6/$B$8*D20 -> 1.35 | F20: =$B$12 -> 10 | G20: =E20+F20 -> 11.35 | H20: =1/(1+$B$7)^C20 -> 0.89007659 | I20: =G20*H20 -> 10.102369 | J20: =I20/$I$26 -> 0.10157851 | K20: =J20*C20 -> 0.48869006 | L20: =C20*(C20+1)*I20 -> 282.42471
A21: 6 | B21: =EDATE(B20,12/$B$8) -> 47802 | C21: =C20+1/$B$8 -> 5.8109589 | D21: =D20-F20 -> 50 | E21: =$B$6/$B$8*D21 -> 1.125 | F21: =$B$12 -> 10 | G21: =E21+F21 -> 11.125 | H21: =1/(1+$B$7)^C21 -> 0.86879121 | I21: =G21*H21 -> 9.6653022 | J21: =I21/$I$26 -> 0.097183839 | K21: =J21*C21 -> 0.5647313 | L21: =C21*(C21+1)*I21 -> 382.53528
A22: 7 | B22: =EDATE(B21,12/$B$8) -> 48167 | C22: =C21+1/$B$8 -> 6.8109589 | D22: =D21-F21 -> 40 | E22: =$B$6/$B$8*D22 -> 0.9 | F22: =$B$12 -> 10 | G22: =E22+F22 -> 10.9 | H22: =1/(1+$B$7)^C22 -> 0.84801484 | I22: =G22*H22 -> 9.2433618 | J22: =I22/$I$26 -> 0.092941263 | K22: =J22*C22 -> 0.63301912 | L22: =C22*(C22+1)*I22 -> 491.74796
A23: 8 | B23: =EDATE(B22,12/$B$8) -> 48533 | C23: =C22+1/$B$8 -> 7.8109589 | D23: =D22-F22 -> 30 | E23: =$B$6/$B$8*D23 -> 0.675 | F23: =$B$12 -> 10 | G23: =E23+F23 -> 10.675 | H23: =1/(1+$B$7)^C23 -> 0.82773533 | I23: =G23*H23 -> 8.8360746 | J23: =I23/$I$26 -> 0.088846023 | K23: =J23*C23 -> 0.69397263 | L23: =C23*(C23+1)*I23 -> 608.11666
A24: 9 | B24: =EDATE(B23,12/$B$8) -> 48898 | C24: =C23+1/$B$8 -> 8.8109589 | D24: =D23-F23 -> 20 | E24: =$B$6/$B$8*D24 -> 0.45 | F24: =$B$12 -> 10 | G24: =E24+F24 -> 10.45 | H24: =1/(1+$B$7)^C24 -> 0.80794078 | I24: =G24*H24 -> 8.4429811 | J24: =I24/$I$26 -> 0.084893499 | K24: =J24*C24 -> 0.74799313 | L24: =C24*(C24+1)*I24 -> 729.84469
A25: 10 | B25: =EDATE(B24,12/$B$8) -> 49263 | C25: =C24+1/$B$8 -> 9.8109589 | D25: =D24-F24 -> 10 | E25: =$B$6/$B$8*D25 -> 0.225 | F25: =$B$12 -> 10 | G25: =E25+F25 -> 10.225 | H25: =1/(1+$B$7)^C25 -> 0.7886196 | I25: =G25*H25 -> 8.0636354 | J25: =I25/$I$26 -> 0.081079208 | K25: =J25*C25 -> 0.79546478 | L25: =C25*(C25+1)*I25 -> 855.27653
A26: Sum | E26: =SUM(E16:E25) -> 12.375 | F26: =SUM(F16:F25) -> 100 | G26: =SUM(G16:G25) -> 112.375 | I26: =SUM(I16:I25) -> 99.4538 | J26: =SUM(J16:J25) -> 1 | K26: =SUM(K16:K25) -> 4.9474262 | L26: =SUM(L16:L25) -> 3737.7876
A27: Rente = kupon × restgæld primo. CF = rente + afdrag. Betalingerne er større tidligt, så vægten flytter frem i tid.
A29: Resultater
A30: Kurs inkl. vedh. rente | B30: =I26 -> 99.4538 | C30: Bogen: 99,454
A31: Macaulay-varighed (år) | B31: =K26 -> 4.9474262 | C31: Bogen: 4,948 år
A32: Modificeret varighed | B32: =B31/(1+B7/B8) -> 4.8291129
A33: Sum t(t+1)·PV(CF) | B33: =L26 -> 3737.7876 | C33: Til konveksitetsafsnittet

Sheet Sammenfatning
A1: Samme endelige løbetid, men forskellig varighed (tabel 4.4)
A3: Obligation | B3: Kurs | C3: Sidste betaling | D3: Macaulay-varighed (år)
A4: Stående obligation | B4: =Stående!B43 -> 98.695624 | C4: =Stående!C38 -> 9.8109589 | D4: =Stående!B46 -> 8.8665589
A5: Serieobligation | B5: =Serieobligation!B30 -> 99.4538 | C5: =Serieobligation!C25 -> 9.8109589 | D5: =Serieobligation!B31 -> 4.9474262
A6: Sidste betaling angivet som tid i år fra valør (bogen: ca. 10 år).
A8: PV-vægte pr. termin – varigheden er 'balancepunktet' for vægtene
A9: Tid i år | B9: Stående | C9: Serie
A10: =Stående!C29 -> 0.8109589 | B10: =Stående!G29 -> 0.022354237 | C10: =Serieobligation!J16 -> 0.12077858
A11: =Stående!C30 -> 1.8109589 | B11: =Stående!G30 -> 0.021819655 | C11: =Serieobligation!J17 -> 0.11572494
A12: =Stående!C31 -> 2.8109589 | B12: =Stående!G31 -> 0.021297858 | C12: =Serieobligation!J18 -> 0.11084393
A13: =Stående!C32 -> 3.8109589 | B13: =Stående!G32 -> 0.020788539 | C13: =Serieobligation!J19 -> 0.10613019
A14: =Stående!C33 -> 4.8109589 | B14: =Stående!G33 -> 0.020291399 | C14: =Serieobligation!J20 -> 0.10157851
A15: =Stående!C34 -> 5.8109589 | B15: =Stående!G34 -> 0.019806149 | C15: =Serieobligation!J21 -> 0.097183839
A16: =Stående!C35 -> 6.8109589 | B16: =Stående!G35 -> 0.019332502 | C16: =Serieobligation!J22 -> 0.092941263
A17: =Stående!C36 -> 7.8109589 | B17: =Stående!G36 -> 0.018870183 | C17: =Serieobligation!J23 -> 0.088846023
A18: =Stående!C37 -> 8.8109589 | B18: =Stående!G37 -> 0.018418919 | C18: =Serieobligation!J24 -> 0.084893499
A19: =Stående!C38 -> 9.8109589 | B19: =Stående!G38 -> 0.81702056 | C19: =Serieobligation!J25 -> 0.081079208

Sheet ACT-ACT vs ACT-365
A1: Dagstællekonvention: ACT/ACT (terminsbaseret) vs. ACT/365 Fixed
A2: ACT/365 Fixed svarer til at trække =DATEDIF(valør;termin;"d")/365 ned. Forskellen opstår, når intervallet indeholder en skuddag.
A4: Valørdag | B4: =Stående!B6 -> 45680
A6: Termin | B6: Faktiske dage fra valør | C6: ACT/ACT | D6: ACT/365 Fixed | E6: Forskel (år) | F6: Skuddag passeret?
A7: =Stående!B29 -> 45976 | B7: =A7-$B$4 -> 296 | C7: =Stående!C29 -> 0.8109589 | D7: =B7/365 -> 0.8109589 | E7: =D7-C7 -> 0 | F7: =IF(ROUND(E7,6)>0,"Ja","Nej") -> Nej
A8: =Stående!B30 -> 46341 | B8: =A8-$B$4 -> 661 | C8: =Stående!C30 -> 1.8109589 | D8: =B8/365 -> 1.8109589 | E8: =D8-C8 -> 0 | F8: =IF(ROUND(E8,6)>0,"Ja","Nej") -> Nej
A9: =Stående!B31 -> 46706 | B9: =A9-$B$4 -> 1026 | C9: =Stående!C31 -> 2.8109589 | D9: =B9/365 -> 2.8109589 | E9: =D9-C9 -> 0 | F9: =IF(ROUND(E9,6)>0,"Ja","Nej") -> Nej
A10: =Stående!B32 -> 47072 | B10: =A10-$B$4 -> 1392 | C10: =Stående!C32 -> 3.8109589 | D10: =B10/365 -> 3.8136986 | E10: =D10-C10 -> 0.002739726 | F10: =IF(ROUND(E10,6)>0,"Ja","Nej") -> Ja
A11: =Stående!B33 -> 47437 | B11: =A11-$B$4 -> 1757 | C11: =Stående!C33 -> 4.8109589 | D11: =B11/365 -> 4.8136986 | E11: =D11-C11 -> 0.002739726 | F11: =IF(ROUND(E11,6)>0,"Ja","Nej") -> Ja
A12: =Stående!B34 -> 47802 | B12: =A12-$B$4 -> 2122 | C12: =Stående!C34 -> 5.8109589 | D12: =B12/365 -> 5.8136986 | E12: =D12-C12 -> 0.002739726 | F12: =IF(ROUND(E12,6)>0,"Ja","Nej") -> Ja
A13: =Stående!B35 -> 48167 | B13: =A13-$B$4 -> 2487 | C13: =Stående!C35 -> 6.8109589 | D13: =B13/365 -> 6.8136986 | E13: =D13-C13 -> 0.002739726 | F13: =IF(ROUND(E13,6)>0,"Ja","Nej") -> Ja
A14: =Stående!B36 -> 48533 | B14: =A14-$B$4 -> 2853 | C14: =Stående!C36 -> 7.8109589 | D14: =B14/365 -> 7.8164384 | E14: =D14-C14 -> 0.0054794521 | F14: =IF(ROUND(E14,6)>0,"Ja","Nej") -> Ja
A15: =Stående!B37 -> 48898 | B15: =A15-$B$4 -> 3218 | C15: =Stående!C37 -> 8.8109589 | D15: =B15/365 -> 8.8164384 | E15: =D15-C15 -> 0.0054794521 | F15: =IF(ROUND(E15,6)>0,"Ja","Nej") -> Ja
A16: =Stående!B38 -> 49263 | B16: =A16-$B$4 -> 3583 | C16: =Stående!C38 -> 9.8109589 | D16: =B16/365 -> 9.8164384 | E16: =D16-C16 -> 0.0054794521 | F16: =IF(ROUND(E16,6)>0,"Ja","Nej") -> Ja
A18: Første skuddag i perioden er 29-02-2028. Fra terminen 15-11-2028 giver ACT/365 ca. 3,814 år mod 3,811 under ACT/ACT, jf. teksten.
